Workbook

Sheet Results
A1: SpOC-3 Torso Decompositions — computational results | J1: Prepared for | K1: AlbShkenca 2026
A2: Scores are negative hypervolume: lower is better. 1,200 s per instance per seed, 3 seeds, best of 3. Every figure is regenerated from harness/*.csv — see “Notes and provenance” for the source file behind each column.
A4: # | B4: Instance | C4: Provable ceiling | D4: fcmaes | E4: Team HRI | F4: Spacekangaroos | G4: Hill Climbing | H4: min-degree ×8 | I4: Best in study | J4: Best method | K4: Margin over 2nd | L4: Verdict | M4: Gap to ceiling | N4: min-degree share | O4: ESA leaderboard
A5: Sparse grid-and-pendant graphs · n = 1,357 · 2,280–2,282 edges · tw ≥ 5 — ceiling nearly reached, no method separates
A6: 1 | B6: small-graph | C6: -1841434 | D6: -1808034 | E6: -1820882 | F6: -1827490 | G6: -1815437 | H6: -1814518 | I6: =MIN(D6:H6) -> -1827490 | J6: =INDEX($D$4:$H$4,MATCH(I6,D6:H6,0)) -> Spacekangaroos | K6: =SMALL(D6:H6,2)-I6 -> 6608 | L6: =IF(K6>=$C$19,"separates","tie") -> tie | M6: =(C6-I6)/C6 -> 0.0075723594 | N6: =H6/I6 -> 0.99290174 | O6: -1829919
A7: 2 | B7: synth-1 | C7: -1841434 | D7: -1804510 | E7: -1818732 | F7: -1816878 | G7: -1819934 | H7: -1818533 | I7: =MIN(D7:H7) -> -1819934 | J7: =INDEX($D$4:$H$4,MATCH(I7,D7:H7,0)) -> Hill Climbing | K7: =SMALL(D7:H7,2)-I7 -> 1202 | L7: =IF(K7>=$C$19,"separates","tie") -> tie | M7: =(C7-I7)/C7 -> 0.011675683 | N7: =H7/I7 -> 0.99923019 | O7: n/a
A8: 3 | B8: synth-2 | C8: -1841434 | D8: -1803847 | E8: -1820165 | F8: -1817483 | G8: -1819958 | H8: -1819873 | I8: =MIN(D8:H8) -> -1820165 | J8: =INDEX($D$4:$H$4,MATCH(I8,D8:H8,0)) -> Team HRI | K8: =SMALL(D8:H8,2)-I8 -> 207 | L8: =IF(K8>=$C$19,"separates","tie") -> tie | M8: =(C8-I8)/C8 -> 0.011550237 | N8: =H8/I8 -> 0.99983957 | O8: n/a
A9: 4 | B9: synth-3 | C9: -1841434 | D9: -1804390 | E9: -1817640 | F9: -1816534 | G9: -1819944 | H9: -1819873 | I9: =MIN(D9:H9) -> -1819944 | J9: =INDEX($D$4:$H$4,MATCH(I9,D9:H9,0)) -> Hill Climbing | K9: =SMALL(D9:H9,2)-I9 -> 71 | L9: =IF(K9>=$C$19,"separates","tie") -> tie | M9: =(C9-I9)/C9 -> 0.011670253 | N9: =H9/I9 -> 0.99996099 | O9: n/a
A10: Rewired medium graphs · n = 1,399 · 13,799 edges · tw ≥ 63–73 — widest apparent gap, but the ceiling here is the loosest
A11: 5 | B11: medium-graph | C11: -1955110 | D11: -1663147 | E11: -1682428 | F11: -1566543 | G11: -1615216 | H11: -1606387 | I11: =MIN(D11:H11) -> -1682428 | J11: =INDEX($D$4:$H$4,MATCH(I11,D11:H11,0)) -> Team HRI | K11: =SMALL(D11:H11,2)-I11 -> 19281 | L11: =IF(K11>=$C$19,"separates","tie") -> separates | M11: =(C11-I11)/C11 -> 0.13947144 | N11: =H11/I11 -> 0.95480282 | O11: -1745122
A12: 6 | B12: synth-4 | C12: -1954471 | D12: -1586305 | E12: -1592317 | F12: -1483952 | G12: -1564037 | H12: -1554095 | I12: =MIN(D12:H12) -> -1592317 | J12: =INDEX($D$4:$H$4,MATCH(I12,D12:H12,0)) -> Team HRI | K12: =SMALL(D12:H12,2)-I12 -> 6012 | L12: =IF(K12>=$C$19,"separates","tie") -> tie | M12: =(C12-I12)/C12 -> 0.18529515 | N12: =H12/I12 -> 0.97599599 | O12: n/a
A13: 7 | B13: synth-5 | C13: -1954395 | D13: -1582930 | E13: -1597450 | F13: -1473387 | G13: -1562142 | H13: -1558465 | I13: =MIN(D13:H13) -> -1597450 | J13: =INDEX($D$4:$H$4,MATCH(I13,D13:H13,0)) -> Team HRI | K13: =SMALL(D13:H13,2)-I13 -> 14520 | L13: =IF(K13>=$C$19,"separates","tie") -> separates | M13: =(C13-I13)/C13 -> 0.18263708 | N13: =H13/I13 -> 0.97559548 | O13: n/a
A14: Clique-pinned dense graphs · n = 2,426 · 253,895 edges · tw pinned to 499–500 — the only family with provably real headroom
A15: 8 | B15: large-graph | C15: -5754421 | D15: -5329389 | E15: -4836783 | F15: — | G15: -4804444 | H15: -4793652 | I15: =MIN(D15:H15) -> -5329389 | J15: =INDEX($D$4:$H$4,MATCH(I15,D15:H15,0)) -> fcmaes | K15: =SMALL(D15:H15,2)-I15 -> 492606 | L15: =IF(K15>=$C$19,"separates","tie") -> separates | M15: =(C15-I15)/C15 -> 0.073861819 | N15: =H15/I15 -> 0.89947497 | O15: -5493062
A16: 9 | B16: synth-6 | C16: -5754421 | D16: -5167178 | E16: -4797902 | F16: — | G16: -4795615 | H16: -4793652 | I16: =MIN(D16:H16) -> -5167178 | J16: =INDEX($D$4:$H$4,MATCH(I16,D16:H16,0)) -> fcmaes | K16: =SMALL(D16:H16,2)-I16 -> 369276 | L16: =IF(K16>=$C$19,"separates","tie") -> separates | M16: =(C16-I16)/C16 -> 0.10205075 | N16: =H16/I16 -> 0.9277118 | O16: n/a
A17: 10 | B17: synth-7 | C17: -5754421 | D17: -5203583 | E17: -4800009 | F17: — | G17: -4795431 | H17: -4793652 | I17: =MIN(D17:H17) -> -5203583 | J17: =INDEX($D$4:$H$4,MATCH(I17,D17:H17,0)) -> fcmaes | K17: =SMALL(D17:H17,2)-I17 -> 403574 | L17: =IF(K17>=$C$19,"separates","tie") -> separates | M17: =(C17-I17)/C17 -> 0.095724314 | N17: =H17/I17 -> 0.9212214 | O17: n/a
A19: Significance floor | C19: 7881 | D19: HV. The most the Hill Climbing baseline differs from an independent run of itself on a single instance (README §13.1). A margin smaller than this is a tie, not a win. Edit this cell and every Verdict re-decides.
A21: Rows won | D21: =D$4 -> fcmaes | E21: =E$4 -> Team HRI | F21: =F$4 -> Spacekangaroos | G21: =G$4 -> Hill Climbing | H21: =H$4 -> min-degree ×8 | I21: of 10
A22: across all 10 instances | D22: =COUNTIF($J$5:$J$17,D$4) -> 3 | E22: =COUNTIF($J$5:$J$17,E$4) -> 4 | F22: =COUNTIF($J$5:$J$17,F$4) -> 1 | G22: =COUNTIF($J$5:$J$17,G$4) -> 2 | H22: =COUNTIF($J$5:$J$17,H$4) -> 0 | I22: =SUM(D22:H22) -> 10
A23: on rows that clear the floor | D23: =COUNTIFS($J$5:$J$17,D$4,$L$5:$L$17,"separates") -> 3 | E23: =COUNTIFS($J$5:$J$17,E$4,$L$5:$L$17,"separates") -> 2 | F23: =COUNTIFS($J$5:$J$17,F$4,$L$5:$L$17,"separates") -> 0 | G23: =COUNTIFS($J$5:$J$17,G$4,$L$5:$L$17,"separates") -> 0 | H23: =COUNTIFS($J$5:$J$17,H$4,$L$5:$L$17,"separates") -> 0 | I23: =COUNTIF($L$5:$L$17,"separates") -> 5
A24: instances it scored on at all | D24: =COUNT(D$5:D$17) -> 10 | E24: =COUNT(E$5:E$17) -> 10 | F24: =COUNT(F$5:F$17) -> 7 | G24: =COUNT(G$5:G$17) -> 10 | H24: =COUNT(H$5:H$17) -> 10 | I24: =COUNTA($B$5:$B$17) -> 10
B26: — in a method column = ran the full 1,200 s and returned no feasible point, not a missing run. “Best in study” is the best of the five columns to its left; it is not the ESA leaderboard figure, which is in the last column and was set under a different protocol. Read “Notes and provenance” before quoting any row.

Sheet Instances
A1: The ten instances — size, structure, and how much room is left
A2: Within each family n and the edge count are identical and only the structure differs, so a ranking that changes between families is a statement about structure rather than size. “Provable ceiling” is bound.py --all: no submission can ever pass it.
A4: # | B4: Instance | C4: Family | D4: n | E4: Edges | F4: tw ≥ | G4: Provable ceiling | H4: Best in study | I4: Gap to ceiling | J4: Legal points from a random ordering | K4: Legal points from min-degree | L4: Origin
A5: 1 | B5: small-graph | C5: Sparse | D5: 1357 | E5: 2280 | F5: 5 | G5: =INDEX(Results!$C$5:$C$17,MATCH($B5,Results!$B$5:$B$17,0)) -> -1841434 | H5: =INDEX(Results!$I$5:$I$17,MATCH($B5,Results!$B$5:$B$17,0)) -> -1827490 | I5: =(G5-H5)/G5 -> 0.0075723594 | J5: 117 | K5: 22 | L5: ESA SpOC-3 official
A6: 2 | B6: synth-1 | C6: Sparse | D6: 1357 | E6: 2282 | F6: 5 | G6: =INDEX(Results!$C$5:$C$17,MATCH($B6,Results!$B$5:$B$17,0)) -> -1841434 | H6: =INDEX(Results!$I$5:$I$17,MATCH($B6,Results!$B$5:$B$17,0)) -> -1819934 | I6: =(G6-H6)/G6 -> 0.011675683 | J6: 250 | K6: 18 | L6: generate.py — 10×115 grid + 207 pendants, seed 1
A7: 3 | B7: synth-2 | C7: Sparse | D7: 1357 | E7: 2282 | F7: 5 | G7: =INDEX(Results!$C$5:$C$17,MATCH($B7,Results!$B$5:$B$17,0)) -> -1841434 | H7: =INDEX(Results!$I$5:$I$17,MATCH($B7,Results!$B$5:$B$17,0)) -> -1820165 | I7: =(G7-H7)/G7 -> 0.011550237 | J7: 297 | K7: 19 | L7: generate.py — same recipe, seed 2
A8: 4 | B8: synth-3 | C8: Sparse | D8: 1357 | E8: 2282 | F8: 5 | G8: =INDEX(Results!$C$5:$C$17,MATCH($B8,Results!$B$5:$B$17,0)) -> -1841434 | H8: =INDEX(Results!$I$5:$I$17,MATCH($B8,Results!$B$5:$B$17,0)) -> -1819944 | I8: =(G8-H8)/G8 -> 0.011670253 | J8: 295 | K8: 19 | L8: generate.py — same recipe, seed 3
A9: 5 | B9: medium-graph | C9: Rewired medium | D9: 1399 | E9: 13799 | F9: 63 | G9: =INDEX(Results!$C$5:$C$17,MATCH($B9,Results!$B$5:$B$17,0)) -> -1955110 | H9: =INDEX(Results!$I$5:$I$17,MATCH($B9,Results!$B$5:$B$17,0)) -> -1682428 | I9: =(G9-H9)/G9 -> 0.13947144 | J9: 0 | K9: 285 | L9: ESA SpOC-3 official
A10: 6 | B10: synth-4 | C10: Rewired medium | D10: 1399 | E10: 13799 | F10: 72 | G10: =INDEX(Results!$C$5:$C$17,MATCH($B10,Results!$B$5:$B$17,0)) -> -1954471 | H10: =INDEX(Results!$I$5:$I$17,MATCH($B10,Results!$B$5:$B$17,0)) -> -1592317 | I10: =(G10-H10)/G10 -> 0.18529515 | J10: 0 | K10: 312 | L10: rewire of medium-graph, seed 1 (1.5% edge overlap)
A11: 7 | B11: synth-5 | C11: Rewired medium | D11: 1399 | E11: 13799 | F11: 73 | G11: =INDEX(Results!$C$5:$C$17,MATCH($B11,Results!$B$5:$B$17,0)) -> -1954395 | H11: =INDEX(Results!$I$5:$I$17,MATCH($B11,Results!$B$5:$B$17,0)) -> -1597450 | I11: =(G11-H11)/G11 -> 0.18263708 | J11: 0 | K11: 349 | L11: rewire of medium-graph, seed 2 (1.5% edge overlap)
A12: 8 | B12: large-graph | C12: Clique-pinned | D12: 2426 | E12: 253895 | F12: 499 | G12: =INDEX(Results!$C$5:$C$17,MATCH($B12,Results!$B$5:$B$17,0)) -> -5754421 | H12: =INDEX(Results!$I$5:$I$17,MATCH($B12,Results!$B$5:$B$17,0)) -> -5329389 | I12: =(G12-H12)/G12 -> 0.073861819 | J12: 0 | K12: 500 | L12: ESA SpOC-3 official — planted 500-clique
A13: 9 | B13: synth-6 | C13: Clique-pinned | D13: 2426 | E13: 253895 | F13: 499 | G13: =INDEX(Results!$C$5:$C$17,MATCH($B13,Results!$B$5:$B$17,0)) -> -5754421 | H13: =INDEX(Results!$I$5:$I$17,MATCH($B13,Results!$B$5:$B$17,0)) -> -5167178 | I13: =(G13-H13)/G13 -> 0.10205075 | J13: 0 | K13: 500 | L13: rewire of large-graph, seed 1 — cliques 500/400/300
A14: 10 | B14: synth-7 | C14: Clique-pinned | D14: 2426 | E14: 253895 | F14: 499 | G14: =INDEX(Results!$C$5:$C$17,MATCH($B14,Results!$B$5:$B$17,0)) -> -5754421 | H14: =INDEX(Results!$I$5:$I$17,MATCH($B14,Results!$B$5:$B$17,0)) -> -5203583 | I14: =(G14-H14)/G14 -> 0.095724314 | J14: 0 | K14: 500 | L14: rewire of large-graph, seed 2 — cliques 500/400/300
B16: Reading the ceiling. A gap is two unknowns added together — how far the best result is from the optimum, plus how far the bound is from the optimum — and they cannot be separated. Where the gap is small both must be small, so the reading is definite: the sparse family is within ~1% of a provable ceiling and is effectively solved. Where it is wide, suspect the bound: on 1,399 vertices a treewidth lower bound of 72 subtracts only ~2,600 from 1,957,201, so the medium family's 14–20% is mostly slack in the bound. The three 2,426-vertex instances are the exception — their treewidth is pinned to 499 or 500, essentially known exactly, so their gap is real headroom. That is where a better construction pays, and where it is measured paying (README §15.3).
B22: Why the starting point is equalised. On six of the ten instances a random ordering yields no legal point at all — every prefix busts the 500-width cap — so a permutation-space solver starting there has nothing to climb and scores 0. Both permutation-space solvers therefore start from the same min-degree construction, computed fresh inside each run. The two weight-space solvers never see a random ordering: their first candidate is already sorted by a degree-and-spectral score (README §10.4).

Sheet Operator ablation
A1: Operator ablation — seventeen move operators against the baseline's own noise
A2: Each row is hill climbing with its move pool restricted to one operator, 1,200 s × 3 seeds × 10 instances, best of 3, summed. Source: harness/ablation_more-*.csv via ablation_more.py.
B4: Baseline sample 1 | D4: -26412158 | E4: benchmark-hill_climbing.csv
B5: Baseline sample 2 | D5: -26390639 | E5: benchmark-hill_climbing-v2.csv — the sample this ablation was scored against
B6: Re-sample error | D6: =ABS(D4-D5) -> 21519 | E6: the same method run twice. Any effect smaller than this is not established.
A8: # | B8: Operator | C8: Family | D8: Total, 10 instances | E8: vs baseline sample 2 | F8: vs baseline sample 1 | G8: Sign flips | H8: Wins | I8: Ties | J8: Losses | K8: Accepted moves | L8: × re-sample error | M8: Verdict | N8: Note
A9: 1 | B9: k_opt_aimed | C9: aimed | D9: -26402010 | E9: =$D$5-D9 -> 11371 | F9: =$D$4-D9 -> -10148 | G9: =IF(SIGN(E9)<>SIGN(F9),"yes","no") -> yes | H9: 2 | I9: 8 | J9: 0 | K9: 53 | L9: =ABS(E9)/ABS($D$6) -> 0.52841675 | M9: =IF(L9>=1,"established","not established") -> not established | N9: the only variant that clears the floor anywhere — on synth-4 and synth-5
A10: 2 | B10: three_opt | C10: k-opt | D10: -26394502 | E10: =$D$5-D10 -> 3863 | F10: =$D$4-D10 -> -17656 | G10: =IF(SIGN(E10)<>SIGN(F10),"yes","no") -> yes | H10: 0 | I10: 10 | J10: 0 | K10: 137 | L10: =ABS(E10)/ABS($D$6) -> 0.17951578 | M10: =IF(L10>=1,"established","not established") -> not established
A11: 3 | B11: corner_shuffle | C11: corner | D11: -26394235 | E11: =$D$5-D11 -> 3596 | F11: =$D$4-D11 -> -17923 | G11: =IF(SIGN(E11)<>SIGN(F11),"yes","no") -> yes | H11: 0 | I11: 10 | J11: 0 | K11: 118 | L11: =ABS(E11)/ABS($D$6) -> 0.16710814 | M11: =IF(L11>=1,"established","not established") -> not established
A12: 4 | B12: or_opt | C12: k-opt | D12: -26393679 | E12: =$D$5-D12 -> 3040 | F12: =$D$4-D12 -> -18479 | G12: =IF(SIGN(E12)<>SIGN(F12),"yes","no") -> yes | H12: 0 | I12: 10 | J12: 0 | K12: 185 | L12: =ABS(E12)/ABS($D$6) -> 0.14127051 | M12: =IF(L12>=1,"established","not established") -> not established
A13: 5 | B13: min_fill_aimed | C13: aimed | D13: -26389902 | E13: =$D$5-D13 -> -737 | F13: =$D$4-D13 -> -22256 | G13: =IF(SIGN(E13)<>SIGN(F13),"yes","no") -> no | H13: 0 | I13: 10 | J13: 0 | K13: 32 | L13: =ABS(E13)/ABS($D$6) -> 0.034248803 | M13: =IF(L13>=1,"established","not established") -> not established
A14: 6 | B14: all 17, competing | C14: all | D14: -26389901 | E14: =$D$5-D14 -> -738 | F14: =$D$4-D14 -> -22257 | G14: =IF(SIGN(E14)<>SIGN(F14),"yes","no") -> no | H14: 0 | I14: 10 | J14: 0 | K14: 537 | L14: =ABS(E14)/ABS($D$6) -> 0.034295274 | M14: =IF(L14>=1,"established","not established") -> not established | N14: the whole pool drawn uniformly
A15: 7 | B15: simplicial_pull | C15: structure | D15: -26389816 | E15: =$D$5-D15 -> -823 | F15: =$D$4-D15 -> -22342 | G15: =IF(SIGN(E15)<>SIGN(F15),"yes","no") -> no | H15: 0 | I15: 10 | J15: 0 | K15: 9 | L15: =ABS(E15)/ABS($D$6) -> 0.038245272 | M15: =IF(L15>=1,"established","not established") -> not established
A16: 8 | B16: k_opt_rotate | C16: k-opt | D16: -26389244 | E16: =$D$5-D16 -> -1395 | F16: =$D$4-D16 -> -22914 | G16: =IF(SIGN(E16)<>SIGN(F16),"yes","no") -> no | H16: 0 | I16: 10 | J16: 0 | K16: 161 | L16: =ABS(E16)/ABS($D$6) -> 0.064826432 | M16: =IF(L16>=1,"established","not established") -> not established
A17: 9 | B17: three_opt_aimed | C17: aimed | D17: -26389039 | E17: =$D$5-D17 -> -1600 | F17: =$D$4-D17 -> -23119 | G17: =IF(SIGN(E17)<>SIGN(F17),"yes","no") -> no | H17: 0 | I17: 10 | J17: 0 | K17: 69 | L17: =ABS(E17)/ABS($D$6) -> 0.074352897 | M17: =IF(L17>=1,"established","not established") -> not established
A18: 10 | B18: min_fill_window | C18: min-fill | D18: -26387771 | E18: =$D$5-D18 -> -2868 | F18: =$D$4-D18 -> -24387 | G18: =IF(SIGN(E18)<>SIGN(F18),"yes","no") -> no | H18: 0 | I18: 10 | J18: 0 | K18: 44 | L18: =ABS(E18)/ABS($D$6) -> 0.13327757 | M18: =IF(L18>=1,"established","not established") -> not established
A19: 11 | B19: degeneracy_window | C19: structure | D19: -26385322 | E19: =$D$5-D19 -> -5317 | F19: =$D$4-D19 -> -26836 | G19: =IF(SIGN(E19)<>SIGN(F19),"yes","no") -> no | H19: 0 | I19: 10 | J19: 0 | K19: 75 | L19: =ABS(E19)/ABS($D$6) -> 0.24708397 | M19: =IF(L19>=1,"established","not established") -> not established
A20: 12 | B20: degeneracy_aimed | C20: aimed | D20: -26384122 | E20: =$D$5-D20 -> -6517 | F20: =$D$4-D20 -> -28036 | G20: =IF(SIGN(E20)<>SIGN(F20),"yes","no") -> no | H20: 0 | I20: 10 | J20: 0 | K20: 9 | L20: =ABS(E20)/ABS($D$6) -> 0.30284865 | M20: =IF(L20>=1,"established","not established") -> not established
A21: 13 | B21: or_opt_aimed | C21: aimed | D21: -26378836 | E21: =$D$5-D21 -> -11803 | F21: =$D$4-D21 -> -33322 | G21: =IF(SIGN(E21)<>SIGN(F21),"yes","no") -> no | H21: 0 | I21: 10 | J21: 0 | K21: 10 | L21: =ABS(E21)/ABS($D$6) -> 0.54849203 | M21: =IF(L21>=1,"established","not established") -> not established
A22: 14 | B22: corner_earlier | C22: corner | D22: -26376380 | E22: =$D$5-D22 -> -14259 | F22: =$D$4-D22 -> -35778 | G22: =IF(SIGN(E22)<>SIGN(F22),"yes","no") -> no | H22: 0 | I22: 10 | J22: 0 | K22: 0 | L22: =ABS(E22)/ABS($D$6) -> 0.66262373 | M22: =IF(L22>=1,"established","not established") -> not established | N22: never fires: zero accepted moves in 30 runs
B24: What the table says. Thirteen of the fourteen variants do not separate from the baseline on a single instance: ten ties, no losses, no wins. The four that come out ahead of baseline sample 2 all come out behind baseline sample 1 — the Sign flips column — so their sign is a property of which run of the control was drawn, not of the operator. The largest effect in the table is 0.7× the amount the baseline differs from itself. An effect that changes sign when the control is re-drawn was never there.
B29: Wins, ties and losses count instances, not seeds: a win is an instance where the variant beats baseline sample 2 by at least the per-instance floor of 7,881 HV, a loss is the same margin the other way. Accepted moves are summed over all 30 runs — corner_earlier accepted nothing at all in 36,000 seconds of searching.

Sheet Budget sweep
A1: Budget sweep — does more time let search catch the construction?
A2: Four arms × three budgets × ten instances × three seeds, best of 3, summed — all on one machine so budget is the only thing that varies. Three budgets rather than two, because two points cannot show the shape of the curve. Source: results/budget_sweep.csv via run_budget_sweep.sh and merge_budget_sweep.py.
A4: Arm | B4: Kind | C4: 1,200 s | D4: 3,600 s | E4: 12,000 s | F4: Gained over 10× budget | G4: Behind construction at 12,000 s | H4: What it is
A5: grasp_front | B5: construction | C5: -26781700 | D5: -26762079 | E5: -26692166 | F5: =C5-E5 -> -89534 | H5: the construction lever — what search has to catch
A6: hill_climbing | B6: search | C6: -26389516 | D6: -26404696 | E6: -26422559 | F6: =C6-E6 -> 33043 | G6: =E6-E$5 -> 269607 | H6: the published four-operator baseline
A7: all 17 | B7: search | C7: -26391399 | D7: -26393577 | E7: -26396957 | F7: =C7-E7 -> 5558 | G7: =E7-E$5 -> 295209 | H7: the seventeen-operator pool
A8: hc_bottleneck | B8: search | C8: -26392654 | D8: -26388897 | E8: -26401668 | F8: =C8-E8 -> 9014 | G8: =E8-E$5 -> 290498 | H8: the move-pool lever
A10: How the construction's lead moves
A11: lead over | C11: 1,200 s | D11: 3,600 s | E11: 12,000 s | F11: closed | G11: % of lead
A12: =A6 -> hill_climbing | C12: =C6-C$5 -> 392184 | D12: =D6-D$5 -> 357383 | E12: =E6-E$5 -> 269607 | F12: =C12-E12 -> 122577 | G12: =(C12-E12)/C12 -> 0.31254972
A13: =A7 -> all 17 | C13: =C7-C$5 -> 390301 | D13: =D7-D$5 -> 368502 | E13: =E7-E$5 -> 295209 | F13: =C13-E13 -> 95092 | G13: =(C13-E13)/C13 -> 0.2436376
A14: =A8 -> hc_bottleneck | C14: =C8-C$5 -> 389046 | D14: =D8-D$5 -> 373182 | E14: =E8-E$5 -> 290498 | F14: =C14-E14 -> 98548 | G14: =(C14-E14)/C14 -> 0.25330681
A16: What it answers. More time does help search — hill climbing gains 33,043 HV going from 1,200 s to 12,000 s, so a claim that extra budget buys nothing would be wrong. It does not help enough. At ten times the published budget the construction still leads the best search arm by 269,607 HV and the ranking does not flip. The lead is closing, by 31% over that 10×, and closing roughly in proportion to budget rather than to its logarithm — which means it would close eventually rather than never. Extrapolating the observed rate puts the crossover near thirty times the published budget, about ten hours per instance. That last sentence is an extrapolation from three points, not a measurement, and it is soft: grasp_front's own total moves by 89,534 HV across these budgets, a third of the gap it is being asked to defend, almost all of it on large-graph and synth-7.
A22: A second reading, which the Operator ablation sheet predicts. The seventeen-operator pool gains 5,558 HV over the same 10× against the four-operator baseline's 33,043, and goes from 1,883 HV ahead of that baseline at 1,200 s to 25,602 HV behind it at 12,000 s. More operators do not merely fail to help — given more budget to spend, they cost.
A26: Scores are negative hypervolume, so a more negative total is better and a positive “gained over 10× budget” means the arm got worse with more time.

Sheet Notes and provenance
B1: Notes and provenance
B2: Read this before quoting any row of Results. Everything below is traceable to a file in this repository; the rule the project keeps is that a number which does not appear in report.py's output does not belong in the sheet.
B6: Protocol
B7: 1,200 s per instance per seed, 3 seeds, best of 3 reported. fcmaes, Team HRI, Hill Climbing and min-degree run on one CPU core each via harness/bench_one.py. Spacekangaroos is the real cuda-torso entry on a Kaggle NVIDIA T4 at batch 1,024, reduced to 512 at n = 2,426 so the two B×N×N bool tensors fit in GPU memory (harness/spoc3_benchmark.ipynb). Every result, whatever produced it, is re-scored and validated through the same esa_eval.py, so the columns are comparable.
B12: Equal wall-clock is not equal computation. The CPU process sat at about 929% — nine cores busy — while Hill Climbing is pure Python and uses exactly one. Measured on small-graph at 30 s, pinning to one core costs fast-cma-es 20% of its evaluations and gains Spacekangaroos 32% of its own (its inner loop is a 104×1,357 matrix-vector product, too small to parallelise, so the BLAS threads spin-wait). The benchmark lets every library thread as its authors intended. The direction of the bias matters: the handicap runs against Hill Climbing, so where it wins a row it wins on one core against opponents using nine (README §10.5).
B19: Where each column comes from
B20: Column | C20: Source file | D20: What it is
B21: Provable ceiling | C21: bound.py --all | D21: The most negative score any method could ever report, from tw(G) ≤ tw(torso(G,S)) + t with a cheap treewidth lower bound. Provable, deterministic, independent of every solver here.
B22: fcmaes | C22: harness/benchmark-fast_cma_es.csv | D22: leaderboard-references/cmaes.py — separable CMA-ES over weight vectors, ported from the fast-cma-es approach. Best of seeds 1–3.
B23: Team HRI | C23: harness/benchmark-hri.csv | D23: leaderboard-references/hri_lns.py — multi-objective LNS reimplemented from their paper; no source was published. Not their code. Best of seeds 1–3.
B24: Spacekangaroos | C24: harness/benchmark-spacekangaroos.csv | D24: The winning entry's own cuda-torso, run unmodified except for a 32-bit overflow fix in libeval.cu (adj_offset int → size_t) and the batch reduction above. Best of seeds 1–3.
B25: Hill Climbing | C25: harness/benchmark-hill_climbing.csv | D25: hill_climbing.py, this study's method. A second independent full-budget sample is in benchmark-hill_climbing-v2.csv; the difference between the two is the significance floor below. Best of seeds 1–3.
B26: min-degree ×8 | C26: harness/benchmark-min_degree-x8.csv | D26: Best of eight greedy min-degree constructions with random tie-breaking, seeds 1–8 — what Hill Climbing builds before it searches. Tie-breaking is random, so the seed set is part of the result. Regenerate with harness/min_degree_x8.py.
B27: Best in study, Best method, Margin, Verdict, Gap, min-degree share | C27: — computed in-sheet | D27: Live formulas over the five method columns. Nothing is typed in; correct a method cell and all six re-derive.
B28: ESA leaderboard | C28: published ESA SpOC-3 leaderboard | D28: Top score on the official three instances only, set under the leaderboard's own protocol — not this benchmark's 1,200 s single-core budget, and not comparable to the columns to its left. The seven synthetic instances are new and have no leaderboard, which is why they read n/a. Kept in the sheet as an external reference point and nothing more.
B31: How big a difference has to be
B32: Hill Climbing was run twice at full budget — ten instances, three seeds, 1,200 s each, both times. The loop is bounded by wall-clock rather than by an iteration count, so the two runs are two independent samples of the same method rather than a repeat. That accident is the most useful measurement in the project, and it yields three different floors which are not interchangeable:
B36: Figure | C36: Value | D36: Use it against
B37: Median within-run seed spread | C37: 1,528 HV | D37: Nothing. Two seeds inside one run share a machine, a thermal state and a session, so their agreement measures much less than it appears to. This chapter used to quote it and it was far too generous.
B38: Worst single instance moved, between the two runs | C38: 7,881 HV | D38: A single row's margin — the Verdict column on Results. This is the floor in use.
B39: Sum over all ten instances | C39: 21,519 HV | D39: A quantity that is also a sum over ten instances, such as an ablation's net-HV column. Holding one row up against this inflates the floor by about the instance count and invents ties that are not there.
B41: Judged against 7,881 HV, five of the ten rows do not separate first place from second: small-graph (6,608), synth-1 (1,202), synth-2 (207), synth-3 (71) and synth-4 (6,012). The method named on those rows won by luck. Only medium-graph, large-graph, synth-5, synth-6 and synth-7 separate the methods by more than the reference method separates from itself — which is why the scoreboard under the table is reported twice, and why the second count is the one to quote.
B46: synth-3 is the clearest case. The 20-minute search reaches −1,819,944; eight min-degree constructions reach −1,819,873 in about two seconds. The search contributes 71 HV, or 0.004%. On the sparse family the bi-objective problem collapses in practice to minimising the width of the whole graph, because a single point at t = 0 carries 99.99% of the score on small-graph — so there is almost nothing left for any search to win there (README §15.4).
B52: What this table does not establish
B53: Three seeds per cell, scored best-of-three. min() over three samples is a biased estimator and the bias is not neutral between methods: it rewards whichever has the higher variance, because best-of-k climbs with spread. A method that is worse on average but noisier prints a better number here. Nothing in this sheet corrects for that.
B57: The floor is itself one sample — a single difference between two runs, not a distribution — so the true spread could be larger. It is used as a lower bound on the noise, the direction that makes the claims harder rather than easier.
B60: Runs are not reproducible, only re-samplable. The climb loop is wall-clock-bounded, so iteration counts differ between sessions and no run here can be reproduced exactly. An attempt to verify a run by re-running it mismatched on 29 of 30 rows, and the check, not the harness, was wrong.
B64: Ten instances, and the dense family is three variants of one graph. large-graph, synth-6 and synth-7 all carry a planted 500-clique, and that family is where every large margin in this table is made. Two of the three were generated to resemble the first, so they are not independently chosen. Any claim about dense instances rests on a thin base.
B68: Half the rows are ties. The Verdict column marks them and the second scoreboard line counts them; the table supports five findings, not ten.
B71: One budget per cell. Everything in Results is 1,200 s, and the construction is a one-off cost paid at the start while the search is what the remaining budget buys — so the ratio between them is a function of the budget. That is no longer an open question: the Budget sweep sheet measures it at 1,200 / 3,600 / 12,000 s and reports what it found.
B76: This revision
B77: Changed | C77: From | D77: To
B78: min-degree ×8 column | C78: no committed source file; 4 of 10 cells not reproducible | D78: harness/benchmark-min_degree-x8.csv + min_degree_x8.py, seeds 1–8. small-graph −1,813,181→−1,814,518 · medium-graph −1,615,495→−1,606,387 · synth-4 −1,553,005→−1,554,095 · synth-5 −1,560,655→−1,558,465. No winner and no verdict changes.
B79: Significance floor | C79: 2,470 HV, described as the median spread across seeds — a figure that appears in no source file | D79: 7,881 HV, the per-instance between-run figure from README §13.1, in an editable cell that drives every Verdict.
B80: Ties | C80: 3 rows marked, by hand | D80: 5 rows, decided by formula. synth-4 and small-graph were missing. synth-3's margin was given as 2,304 HV against Team HRI when second place is min-degree ×8.
B81: “Best Known” | C81: one column holding the ESA leaderboard top on three rows and the in-study best on seven — two different things under two different protocols | D81: split into Best in study (formula over the five method columns) and ESA leaderboard (external, official three instances only).
B82: “Gap from Best” | C82: labelled as the gap from best, but the formula read column I and so silently reported Hill Climbing's gap. Its reference column was empty, so it rendered blank throughout | D82: Gap to ceiling — best in study against the provable bound from bound.py. Plus min-degree share, which is the construction-versus-search comparison the write-up is about.
B83: Upper Bound column | C83: present and completely empty | D83: filled for all ten instances from bound.py --all, and the spine of the Instances sheet.
B84: Row order | C84: official three, then synth-1–7 | D84: grouped into the three structural families, each a set of matched instances with identical n and edge count. The ranking changes between families; that is the result.
B85: Readability | C85: every data cell filled dark teal #356854 with theme-black text, header row unfilled; footnotes living inside the table body as instance rows 11–18; three Excel tables stretched over 290 empty rows; no frozen header | D85: dark band reserved for the header, light zebra body, winners highlighted, notes moved here, empty rows and the three empty columns removed, header frozen and set to repeat on every printed page.
...
