Workbook

Sheet Results
A1: SpOC-3 Torso Decompositions — computational results | J1: Prepared for | K1: AlbShkenca 2026
A2: Scores are negative hypervolume: lower is better. 1,200 s per instance per seed, 3 seeds; the method columns show the best of 3. Verdicts are read from each method's own three seeds (Seeds sheet). Every figure is regenerated from harness/*.csv — see “Notes and provenance”.
A4: # | B4: Instance | C4: Provable ceiling | D4: fcmaes | E4: Team HRI | F4: Spacekangaroos | G4: Hill Climbing | H4: min-degree ×8 | I4: Best in study | J4: Best method | K4: Margin over 2nd | L4: Verdict (seeds) | M4: Gap to ceiling | N4: min-degree share | O4: ESA leaderboard | P4: Median winner | Q4: Seed gap | R4: Floor rule (v3)
A5: Sparse grid-and-pendant graphs · n = 1,357 · 2,280–2,282 edges · tw ≥ 5 — ceiling nearly reached, no method separates
A6: 1 | B6: small-graph | C6: -1841434 | D6: -1808034 | E6: -1820882 | F6: -1827490 | G6: -1815437 | H6: -1814518 | I6: =MIN(D6:H6) -> -1827490 | J6: =INDEX($D$4:$H$4,MATCH(I6,D6:H6,0)) -> Spacekangaroos | K6: =SMALL(D6:H6,2)-I6 -> 6608 | L6: =IF(AND($P6=$J6,$Q6>0),"resolved","unresolved") -> unresolved | M6: =(C6-I6)/C6 -> 0.0075723594 | N6: =H6/I6 -> 0.99290174 | O6: -1829919 | P6: =INDEX(Seeds!$P$5:$T$5,MATCH(MIN(INDEX(Seeds!$P$6:$T$15,MATCH($B6,Seeds!$B$6:$B$15,0),0)),INDEX(Seeds!$P$6:$T$15,MATCH($B6,Seeds!$B$6:$B$15,0),0),0)) -> Team HRI | Q6: =SMALL($D6:$H6,2)-INDEX(Seeds!$U$6:$Y$15,MATCH($B6,Seeds!$B$6:$B$15,0),MATCH($J6,Seeds!$U$5:$Y$5,0)) -> -9960 | R6: =IF($K6>=$C$19,"separates","tie") -> tie
A7: 2 | B7: synth-1 | C7: -1841434 | D7: -1804510 | E7: -1818732 | F7: -1816878 | G7: -1819934 | H7: -1818533 | I7: =MIN(D7:H7) -> -1819934 | J7: =INDEX($D$4:$H$4,MATCH(I7,D7:H7,0)) -> Hill Climbing | K7: =SMALL(D7:H7,2)-I7 -> 1202 | L7: =IF(AND($P7=$J7,$Q7>0),"resolved","unresolved") -> unresolved | M7: =(C7-I7)/C7 -> 0.011675683 | N7: =H7/I7 -> 0.99923019 | O7: n/a | P7: =INDEX(Seeds!$P$5:$T$5,MATCH(MIN(INDEX(Seeds!$P$6:$T$15,MATCH($B7,Seeds!$B$6:$B$15,0),0)),INDEX(Seeds!$P$6:$T$15,MATCH($B7,Seeds!$B$6:$B$15,0),0),0)) -> Hill Climbing | Q7: =SMALL($D7:$H7,2)-INDEX(Seeds!$U$6:$Y$15,MATCH($B7,Seeds!$B$6:$B$15,0),MATCH($J7,Seeds!$U$5:$Y$5,0)) -> -120 | R7: =IF($K7>=$C$19,"separates","tie") -> tie
A8: 3 | B8: synth-2 | C8: -1841434 | D8: -1803847 | E8: -1820165 | F8: -1817483 | G8: -1819958 | H8: -1819873 | I8: =MIN(D8:H8) -> -1820165 | J8: =INDEX($D$4:$H$4,MATCH(I8,D8:H8,0)) -> Team HRI | K8: =SMALL(D8:H8,2)-I8 -> 207 | L8: =IF(AND($P8=$J8,$Q8>0),"resolved","unresolved") -> unresolved | M8: =(C8-I8)/C8 -> 0.011550237 | N8: =H8/I8 -> 0.99983957 | O8: n/a | P8: =INDEX(Seeds!$P$5:$T$5,MATCH(MIN(INDEX(Seeds!$P$6:$T$15,MATCH($B8,Seeds!$B$6:$B$15,0),0)),INDEX(Seeds!$P$6:$T$15,MATCH($B8,Seeds!$B$6:$B$15,0),0),0)) -> Hill Climbing | Q8: =SMALL($D8:$H8,2)-INDEX(Seeds!$U$6:$Y$15,MATCH($B8,Seeds!$B$6:$B$15,0),MATCH($J8,Seeds!$U$5:$Y$5,0)) -> -2515 | R8: =IF($K8>=$C$19,"separates","tie") -> tie
A9: 4 | B9: synth-3 | C9: -1841434 | D9: -1804390 | E9: -1817640 | F9: -1816534 | G9: -1819944 | H9: -1819873 | I9: =MIN(D9:H9) -> -1819944 | J9: =INDEX($D$4:$H$4,MATCH(I9,D9:H9,0)) -> Hill Climbing | K9: =SMALL(D9:H9,2)-I9 -> 71 | L9: =IF(AND($P9=$J9,$Q9>0),"resolved","unresolved") -> resolved | M9: =(C9-I9)/C9 -> 0.011670253 | N9: =H9/I9 -> 0.99996099 | O9: n/a | P9: =INDEX(Seeds!$P$5:$T$5,MATCH(MIN(INDEX(Seeds!$P$6:$T$15,MATCH($B9,Seeds!$B$6:$B$15,0),0)),INDEX(Seeds!$P$6:$T$15,MATCH($B9,Seeds!$B$6:$B$15,0),0),0)) -> Hill Climbing | Q9: =SMALL($D9:$H9,2)-INDEX(Seeds!$U$6:$Y$15,MATCH($B9,Seeds!$B$6:$B$15,0),MATCH($J9,Seeds!$U$5:$Y$5,0)) -> 24 | R9: =IF($K9>=$C$19,"separates","tie") -> tie
A10: Rewired medium graphs · n = 1,399 · 13,799 edges · tw ≥ 63–73 — widest apparent gap, but the ceiling here is the loosest
A11: 5 | B11: medium-graph | C11: -1955110 | D11: -1663147 | E11: -1682428 | F11: -1566543 | G11: -1615216 | H11: -1606387 | I11: =MIN(D11:H11) -> -1682428 | J11: =INDEX($D$4:$H$4,MATCH(I11,D11:H11,0)) -> Team HRI | K11: =SMALL(D11:H11,2)-I11 -> 19281 | L11: =IF(AND($P11=$J11,$Q11>0),"resolved","unresolved") -> unresolved | M11: =(C11-I11)/C11 -> 0.13947144 | N11: =H11/I11 -> 0.95480282 | O11: -1745122 | P11: =INDEX(Seeds!$P$5:$T$5,MATCH(MIN(INDEX(Seeds!$P$6:$T$15,MATCH($B11,Seeds!$B$6:$B$15,0),0)),INDEX(Seeds!$P$6:$T$15,MATCH($B11,Seeds!$B$6:$B$15,0),0),0)) -> Team HRI | Q11: =SMALL($D11:$H11,2)-INDEX(Seeds!$U$6:$Y$15,MATCH($B11,Seeds!$B$6:$B$15,0),MATCH($J11,Seeds!$U$5:$Y$5,0)) -> -61095 | R11: =IF($K11>=$C$19,"separates","tie") -> separates
A12: 6 | B12: synth-4 | C12: -1954471 | D12: -1586305 | E12: -1592317 | F12: -1483952 | G12: -1564037 | H12: -1554095 | I12: =MIN(D12:H12) -> -1592317 | J12: =INDEX($D$4:$H$4,MATCH(I12,D12:H12,0)) -> Team HRI | K12: =SMALL(D12:H12,2)-I12 -> 6012 | L12: =IF(AND($P12=$J12,$Q12>0),"resolved","unresolved") -> resolved | M12: =(C12-I12)/C12 -> 0.18529515 | N12: =H12/I12 -> 0.97599599 | O12: n/a | P12: =INDEX(Seeds!$P$5:$T$5,MATCH(MIN(INDEX(Seeds!$P$6:$T$15,MATCH($B12,Seeds!$B$6:$B$15,0),0)),INDEX(Seeds!$P$6:$T$15,MATCH($B12,Seeds!$B$6:$B$15,0),0),0)) -> Team HRI | Q12: =SMALL($D12:$H12,2)-INDEX(Seeds!$U$6:$Y$15,MATCH($B12,Seeds!$B$6:$B$15,0),MATCH($J12,Seeds!$U$5:$Y$5,0)) -> 2128 | R12: =IF($K12>=$C$19,"separates","tie") -> tie
A13: 7 | B13: synth-5 | C13: -1954395 | D13: -1582930 | E13: -1597450 | F13: -1473387 | G13: -1562142 | H13: -1558465 | I13: =MIN(D13:H13) -> -1597450 | J13: =INDEX($D$4:$H$4,MATCH(I13,D13:H13,0)) -> Team HRI | K13: =SMALL(D13:H13,2)-I13 -> 14520 | L13: =IF(AND($P13=$J13,$Q13>0),"resolved","unresolved") -> unresolved | M13: =(C13-I13)/C13 -> 0.18263708 | N13: =H13/I13 -> 0.97559548 | O13: n/a | P13: =INDEX(Seeds!$P$5:$T$5,MATCH(MIN(INDEX(Seeds!$P$6:$T$15,MATCH($B13,Seeds!$B$6:$B$15,0),0)),INDEX(Seeds!$P$6:$T$15,MATCH($B13,Seeds!$B$6:$B$15,0),0),0)) -> fcmaes | Q13: =SMALL($D13:$H13,2)-INDEX(Seeds!$U$6:$Y$15,MATCH($B13,Seeds!$B$6:$B$15,0),MATCH($J13,Seeds!$U$5:$Y$5,0)) -> -31077 | R13: =IF($K13>=$C$19,"separates","tie") -> separates
A14: Clique-pinned dense graphs · n = 2,426 · 253,895 edges · tw pinned to 499–500 — the only family with provably real headroom
A15: 8 | B15: large-graph | C15: -5754421 | D15: -5329389 | E15: -4836783 | F15: — | G15: -4804444 | H15: -4793652 | I15: =MIN(D15:H15) -> -5329389 | J15: =INDEX($D$4:$H$4,MATCH(I15,D15:H15,0)) -> fcmaes | K15: =SMALL(D15:H15,2)-I15 -> 492606 | L15: =IF(AND($P15=$J15,$Q15>0),"resolved","unresolved") -> resolved | M15: =(C15-I15)/C15 -> 0.073861819 | N15: =H15/I15 -> 0.89947497 | O15: -5493062 | P15: =INDEX(Seeds!$P$5:$T$5,MATCH(MIN(INDEX(Seeds!$P$6:$T$15,MATCH($B15,Seeds!$B$6:$B$15,0),0)),INDEX(Seeds!$P$6:$T$15,MATCH($B15,Seeds!$B$6:$B$15,0),0),0)) -> fcmaes | Q15: =SMALL($D15:$H15,2)-INDEX(Seeds!$U$6:$Y$15,MATCH($B15,Seeds!$B$6:$B$15,0),MATCH($J15,Seeds!$U$5:$Y$5,0)) -> 425344 | R15: =IF($K15>=$C$19,"separates","tie") -> separates
A16: 9 | B16: synth-6 | C16: -5754421 | D16: -5167178 | E16: -4797902 | F16: — | G16: -4795615 | H16: -4793652 | I16: =MIN(D16:H16) -> -5167178 | J16: =INDEX($D$4:$H$4,MATCH(I16,D16:H16,0)) -> fcmaes | K16: =SMALL(D16:H16,2)-I16 -> 369276 | L16: =IF(AND($P16=$J16,$Q16>0),"resolved","unresolved") -> resolved | M16: =(C16-I16)/C16 -> 0.10205075 | N16: =H16/I16 -> 0.9277118 | O16: n/a | P16: =INDEX(Seeds!$P$5:$T$5,MATCH(MIN(INDEX(Seeds!$P$6:$T$15,MATCH($B16,Seeds!$B$6:$B$15,0),0)),INDEX(Seeds!$P$6:$T$15,MATCH($B16,Seeds!$B$6:$B$15,0),0),0)) -> fcmaes | Q16: =SMALL($D16:$H16,2)-INDEX(Seeds!$U$6:$Y$15,MATCH($B16,Seeds!$B$6:$B$15,0),MATCH($J16,Seeds!$U$5:$Y$5,0)) -> 233811 | R16: =IF($K16>=$C$19,"separates","tie") -> separates
A17: 10 | B17: synth-7 | C17: -5754421 | D17: -5203583 | E17: -4800009 | F17: — | G17: -4795431 | H17: -4793652 | I17: =MIN(D17:H17) -> -5203583 | J17: =INDEX($D$4:$H$4,MATCH(I17,D17:H17,0)) -> fcmaes | K17: =SMALL(D17:H17,2)-I17 -> 403574 | L17: =IF(AND($P17=$J17,$Q17>0),"resolved","unresolved") -> resolved | M17: =(C17-I17)/C17 -> 0.095724314 | N17: =H17/I17 -> 0.9212214 | O17: n/a | P17: =INDEX(Seeds!$P$5:$T$5,MATCH(MIN(INDEX(Seeds!$P$6:$T$15,MATCH($B17,Seeds!$B$6:$B$15,0),0)),INDEX(Seeds!$P$6:$T$15,MATCH($B17,Seeds!$B$6:$B$15,0),0),0)) -> fcmaes | Q17: =SMALL($D17:$H17,2)-INDEX(Seeds!$U$6:$Y$15,MATCH($B17,Seeds!$B$6:$B$15,0),MATCH($J17,Seeds!$U$5:$Y$5,0)) -> 121598 | R17: =IF($K17>=$C$19,"separates","tie") -> separates
A19: Significance floor | C19: 7881 | D19: HV. Shown for comparison only: the most Hill Climbing's best-of-3 moved between two full sessions on one instance (synth-4), applied in v3 to every method and row. It drives the Floor rule (v3) column; the Verdict column uses each method's own seeds instead.
A21: Rows won | D21: =D$4 -> fcmaes | E21: =E$4 -> Team HRI | F21: =F$4 -> Spacekangaroos | G21: =G$4 -> Hill Climbing | H21: =H$4 -> min-degree ×8 | I21: of 10
A22: best of 3, all ten rows | D22: =COUNTIF($J$5:$J$17,D$4) -> 3 | E22: =COUNTIF($J$5:$J$17,E$4) -> 4 | F22: =COUNTIF($J$5:$J$17,F$4) -> 1 | G22: =COUNTIF($J$5:$J$17,G$4) -> 2 | H22: =COUNTIF($J$5:$J$17,H$4) -> 0 | I22: =SUM(D22:H22) -> 10
A23: median of 3, all ten rows | D23: =COUNTIF($P$5:$P$17,D$4) -> 4 | E23: =COUNTIF($P$5:$P$17,E$4) -> 3 | F23: =COUNTIF($P$5:$P$17,F$4) -> 0 | G23: =COUNTIF($P$5:$P$17,G$4) -> 3 | H23: =COUNTIF($P$5:$P$17,H$4) -> 0 | I23: =SUM(D23:H23) -> 10
A24: resolved rows only | D24: =COUNTIFS($J$5:$J$17,D$4,$L$5:$L$17,"resolved") -> 3 | E24: =COUNTIFS($J$5:$J$17,E$4,$L$5:$L$17,"resolved") -> 1 | F24: =COUNTIFS($J$5:$J$17,F$4,$L$5:$L$17,"resolved") -> 0 | G24: =COUNTIFS($J$5:$J$17,G$4,$L$5:$L$17,"resolved") -> 1 | H24: =COUNTIFS($J$5:$J$17,H$4,$L$5:$L$17,"resolved") -> 0 | I24: =COUNTIF($L$5:$L$17,"resolved") -> 5
A25: clearing 7,881 HV (v3 rule) | D25: =COUNTIFS($J$5:$J$17,D$4,$R$5:$R$17,"separates") -> 3 | E25: =COUNTIFS($J$5:$J$17,E$4,$R$5:$R$17,"separates") -> 2 | F25: =COUNTIFS($J$5:$J$17,F$4,$R$5:$R$17,"separates") -> 0 | G25: =COUNTIFS($J$5:$J$17,G$4,$R$5:$R$17,"separates") -> 0 | H25: =COUNTIFS($J$5:$J$17,H$4,$R$5:$R$17,"separates") -> 0 | I25: =COUNTIF($R$5:$R$17,"separates") -> 5
A26: instances it scored on at all | D26: =COUNT(D$5:D$17) -> 10 | E26: =COUNT(E$5:E$17) -> 10 | F26: =COUNT(F$5:F$17) -> 7 | G26: =COUNT(G$5:G$17) -> 10 | H26: =COUNT(H$5:H$17) -> 10 | I26: =COUNTA($B$5:$B$17) -> 10
B28: — in a method column = ran the full 1,200 s and returned no point under the 500-width cap, not a missing run. “Best in study” is the best of the five columns to its left; it is not the ESA leaderboard figure, which is in column O and was set under a different protocol. Seed gap = the runner-up's best seed minus the winner's worst seed: positive means every seed of the winner beats every seed of every rival (min-degree ×8 is one value). A row is resolved when that holds and the median names the same winner. Read “Notes and provenance” before quoting any row.

Sheet Seeds
A1: Seeds — every run behind the Results sheet
A2: Three seeds per method and instance, 1,200 s each, every one re-scored through esa_eval.py. Scores are negative hypervolume, so lower is better: the median and the worst seed are read here, the best is on Results. min-degree ×8 is one deterministic value (best of eight tie-break seeds). — marks a run that returned no point under the 500-width cap. Source: harness/benchmark-*.csv; harness/robustness.py prints the same verdicts.
A4: # | B4: Instance | C4: fcmaes | F4: Team HRI | I4: Spacekangaroos | L4: Hill Climbing | O4: min-degree ×8 | P4: Median of 3 | U4: Worst of 3
C5: seed 1 | D5: seed 2 | E5: seed 3 | F5: seed 1 | G5: seed 2 | H5: seed 3 | I5: seed 1 | J5: seed 2 | K5: seed 3 | L5: seed 1 | M5: seed 2 | N5: seed 3 | O5: seeds 1–8 | P5: fcmaes | Q5: Team HRI | R5: Spacekangaroos | S5: Hill Climbing | T5: min-degree ×8 | U5: fcmaes | V5: Team HRI | W5: Spacekangaroos | X5: Hill Climbing | Y5: min-degree ×8
A6: 1 | B6: small-graph | C6: -1807719 | D6: -1808034 | E6: -1807148 | F6: -1820882 | G6: -1819464 | H6: -1818926 | I6: -1827490 | J6: -1812221 | K6: -1810922 | L6: -1814530 | M6: -1815437 | N6: -1814547 | O6: -1814518 | P6: =IF(COUNT(C6:E6)=0,"—",MEDIAN(C6:E6)) -> -1807719 | Q6: =IF(COUNT(F6:H6)=0,"—",MEDIAN(F6:H6)) -> -1819464 | R6: =IF(COUNT(I6:K6)=0,"—",MEDIAN(I6:K6)) -> -1812221 | S6: =IF(COUNT(L6:N6)=0,"—",MEDIAN(L6:N6)) -> -1814547 | T6: =O6 -> -1814518 | U6: =IF(COUNT(C6:E6)=0,"—",MAX(C6:E6)) -> -1807148 | V6: =IF(COUNT(F6:H6)=0,"—",MAX(F6:H6)) -> -1818926 | W6: =IF(COUNT(I6:K6)=0,"—",MAX(I6:K6)) -> -1810922 | X6: =IF(COUNT(L6:N6)=0,"—",MAX(L6:N6)) -> -1814530 | Y6: =O6 -> -1814518
A7: 2 | B7: synth-1 | C7: -1804199 | D7: -1803399 | E7: -1804510 | F7: -1818732 | G7: -1814806 | H7: -1818062 | I7: -1816878 | J7: -1815564 | K7: -1815654 | L7: -1819934 | M7: -1818612 | N7: -1818742 | O7: -1818533 | P7: =IF(COUNT(C7:E7)=0,"—",MEDIAN(C7:E7)) -> -1804199 | Q7: =IF(COUNT(F7:H7)=0,"—",MEDIAN(F7:H7)) -> -1818062 | R7: =IF(COUNT(I7:K7)=0,"—",MEDIAN(I7:K7)) -> -1815654 | S7: =IF(COUNT(L7:N7)=0,"—",MEDIAN(L7:N7)) -> -1818742 | T7: =O7 -> -1818533 | U7: =IF(COUNT(C7:E7)=0,"—",MAX(C7:E7)) -> -1803399 | V7: =IF(COUNT(F7:H7)=0,"—",MAX(F7:H7)) -> -1814806 | W7: =IF(COUNT(I7:K7)=0,"—",MAX(I7:K7)) -> -1815564 | X7: =IF(COUNT(L7:N7)=0,"—",MAX(L7:N7)) -> -1818612 | Y7: =O7 -> -1818533
A8: 3 | B8: synth-2 | C8: -1803847 | D8: -1802840 | E8: -1803596 | F8: -1817443 | G8: -1820165 | H8: -1817634 | I8: -1817483 | J8: -1815355 | K8: -1815756 | L8: -1819894 | M8: -1819958 | N8: -1819911 | O8: -1819873 | P8: =IF(COUNT(C8:E8)=0,"—",MEDIAN(C8:E8)) -> -1803596 | Q8: =IF(COUNT(F8:H8)=0,"—",MEDIAN(F8:H8)) -> -1817634 | R8: =IF(COUNT(I8:K8)=0,"—",MEDIAN(I8:K8)) -> -1815756 | S8: =IF(COUNT(L8:N8)=0,"—",MEDIAN(L8:N8)) -> -1819911 | T8: =O8 -> -1819873 | U8: =IF(COUNT(C8:E8)=0,"—",MAX(C8:E8)) -> -1802840 | V8: =IF(COUNT(F8:H8)=0,"—",MAX(F8:H8)) -> -1817443 | W8: =IF(COUNT(I8:K8)=0,"—",MAX(I8:K8)) -> -1815355 | X8: =IF(COUNT(L8:N8)=0,"—",MAX(L8:N8)) -> -1819894 | Y8: =O8 -> -1819873
A9: 4 | B9: synth-3 | C9: -1803163 | D9: -1804271 | E9: -1804390 | F9: -1817640 | G9: -1816338 | H9: -1816772 | I9: -1816534 | J9: -1814924 | K9: -1815948 | L9: -1819897 | M9: -1819942 | N9: -1819944 | O9: -1819873 | P9: =IF(COUNT(C9:E9)=0,"—",MEDIAN(C9:E9)) -> -1804271 | Q9: =IF(COUNT(F9:H9)=0,"—",MEDIAN(F9:H9)) -> -1816772 | R9: =IF(COUNT(I9:K9)=0,"—",MEDIAN(I9:K9)) -> -1815948 | S9: =IF(COUNT(L9:N9)=0,"—",MEDIAN(L9:N9)) -> -1819942 | T9: =O9 -> -1819873 | U9: =IF(COUNT(C9:E9)=0,"—",MAX(C9:E9)) -> -1803163 | V9: =IF(COUNT(F9:H9)=0,"—",MAX(F9:H9)) -> -1816338 | W9: =IF(COUNT(I9:K9)=0,"—",MAX(I9:K9)) -> -1814924 | X9: =IF(COUNT(L9:N9)=0,"—",MAX(L9:N9)) -> -1819897 | Y9: =O9 -> -1819873
A10: 5 | B10: medium-graph | C10: -1659249 | D10: -1663147 | E10: -1658182 | F10: -1674300 | G10: -1682428 | H10: -1602052 | I10: -1566543 | J10: -1544821 | K10: -1546986 | L10: -1615216 | M10: -1612542 | N10: -1608489 | O10: -1606387 | P10: =IF(COUNT(C10:E10)=0,"—",MEDIAN(C10:E10)) -> -1659249 | Q10: =IF(COUNT(F10:H10)=0,"—",MEDIAN(F10:H10)) -> -1674300 | R10: =IF(COUNT(I10:K10)=0,"—",MEDIAN(I10:K10)) -> -1546986 | S10: =IF(COUNT(L10:N10)=0,"—",MEDIAN(L10:N10)) -> -1612542 | T10: =O10 -> -1606387 | U10: =IF(COUNT(C10:E10)=0,"—",MAX(C10:E10)) -> -1658182 | V10: =IF(COUNT(F10:H10)=0,"—",MAX(F10:H10)) -> -1602052 | W10: =IF(COUNT(I10:K10)=0,"—",MAX(I10:K10)) -> -1544821 | X10: =IF(COUNT(L10:N10)=0,"—",MAX(L10:N10)) -> -1608489 | Y10: =O10 -> -1606387
A11: 6 | B11: synth-4 | C11: -1585523 | D11: -1586305 | E11: -1584087 | F11: -1592293 | G11: -1588433 | H11: -1592317 | I11: -1470135 | J11: -1483952 | K11: -1482556 | L11: -1551822 | M11: -1550823 | N11: -1564037 | O11: -1554095 | P11: =IF(COUNT(C11:E11)=0,"—",MEDIAN(C11:E11)) -> -1585523 | Q11: =IF(COUNT(F11:H11)=0,"—",MEDIAN(F11:H11)) -> -1592293 | R11: =IF(COUNT(I11:K11)=0,"—",MEDIAN(I11:K11)) -> -1482556 | S11: =IF(COUNT(L11:N11)=0,"—",MEDIAN(L11:N11)) -> -1551822 | T11: =O11 -> -1554095 | U11: =IF(COUNT(C11:E11)=0,"—",MAX(C11:E11)) -> -1584087 | V11: =IF(COUNT(F11:H11)=0,"—",MAX(F11:H11)) -> -1588433 | W11: =IF(COUNT(I11:K11)=0,"—",MAX(I11:K11)) -> -1470135 | X11: =IF(COUNT(L11:N11)=0,"—",MAX(L11:N11)) -> -1550823 | Y11: =O11 -> -1554095
A12: 7 | B12: synth-5 | C12: -1578844 | D12: -1581827 | E12: -1582930 | F12: -1554874 | G12: -1551853 | H12: -1597450 | I12: -1465258 | J12: -1473387 | K12: -1462223 | L12: -1562142 | M12: -1554222 | N12: -1551628 | O12: -1558465 | P12: =IF(COUNT(C12:E12)=0,"—",MEDIAN(C12:E12)) -> -1581827 | Q12: =IF(COUNT(F12:H12)=0,"—",MEDIAN(F12:H12)) -> -1554874 | R12: =IF(COUNT(I12:K12)=0,"—",MEDIAN(I12:K12)) -> -1465258 | S12: =IF(COUNT(L12:N12)=0,"—",MEDIAN(L12:N12)) -> -1554222 | T12: =O12 -> -1558465 | U12: =IF(COUNT(C12:E12)=0,"—",MAX(C12:E12)) -> -1578844 | V12: =IF(COUNT(F12:H12)=0,"—",MAX(F12:H12)) -> -1551853 | W12: =IF(COUNT(I12:K12)=0,"—",MAX(I12:K12)) -> -1462223 | X12: =IF(COUNT(L12:N12)=0,"—",MAX(L12:N12)) -> -1551628 | Y12: =O12 -> -1558465
A13: 8 | B13: large-graph | C13: -5329389 | D13: -5290070 | E13: -5262127 | F13: -4829467 | G13: -4836783 | H13: -4834244 | I13: — | J13: — | K13: — | L13: -4796797 | M13: -4800393 | N13: -4804444 | O13: -4793652 | P13: =IF(COUNT(C13:E13)=0,"—",MEDIAN(C13:E13)) -> -5290070 | Q13: =IF(COUNT(F13:H13)=0,"—",MEDIAN(F13:H13)) -> -4834244 | R13: =IF(COUNT(I13:K13)=0,"—",MEDIAN(I13:K13)) -> — | S13: =IF(COUNT(L13:N13)=0,"—",MEDIAN(L13:N13)) -> -4800393 | T13: =O13 -> -4793652 | U13: =IF(COUNT(C13:E13)=0,"—",MAX(C13:E13)) -> -5262127 | V13: =IF(COUNT(F13:H13)=0,"—",MAX(F13:H13)) -> -4829467 | W13: =IF(COUNT(I13:K13)=0,"—",MAX(I13:K13)) -> — | X13: =IF(COUNT(L13:N13)=0,"—",MAX(L13:N13)) -> -4796797 | Y13: =O13 -> -4793652
A14: 9 | B14: synth-6 | C14: -5167178 | D14: -5056039 | E14: -5031713 | F14: -4795794 | G14: -4796236 | H14: -4797902 | I14: — | J14: — | K14: — | L14: -4795457 | M14: -4795376 | N14: -4795615 | O14: -4793652 | P14: =IF(COUNT(C14:E14)=0,"—",MEDIAN(C14:E14)) -> -5056039 | Q14: =IF(COUNT(F14:H14)=0,"—",MEDIAN(F14:H14)) -> -4796236 | R14: =IF(COUNT(I14:K14)=0,"—",MEDIAN(I14:K14)) -> — | S14: =IF(COUNT(L14:N14)=0,"—",MEDIAN(L14:N14)) -> -4795457 | T14: =O14 -> -4793652 | U14: =IF(COUNT(C14:E14)=0,"—",MAX(C14:E14)) -> -5031713 | V14: =IF(COUNT(F14:H14)=0,"—",MAX(F14:H14)) -> -4795794 | W14: =IF(COUNT(I14:K14)=0,"—",MAX(I14:K14)) -> — | X14: =IF(COUNT(L14:N14)=0,"—",MAX(L14:N14)) -> -4795376 | Y14: =O14 -> -4793652
A15: 10 | B15: synth-7 | C15: -4930101 | D15: -4921607 | E15: -5203583 | F15: -4794398 | G15: -4795646 | H15: -4800009 | I15: — | J15: — | K15: — | L15: -4795431 | M15: -4795315 | N15: -4795299 | O15: -4793652 | P15: =IF(COUNT(C15:E15)=0,"—",MEDIAN(C15:E15)) -> -4930101 | Q15: =IF(COUNT(F15:H15)=0,"—",MEDIAN(F15:H15)) -> -4795646 | R15: =IF(COUNT(I15:K15)=0,"—",MEDIAN(I15:K15)) -> — | S15: =IF(COUNT(L15:N15)=0,"—",MEDIAN(L15:N15)) -> -4795315 | T15: =O15 -> -4793652 | U15: =IF(COUNT(C15:E15)=0,"—",MAX(C15:E15)) -> -4921607 | V15: =IF(COUNT(F15:H15)=0,"—",MAX(F15:H15)) -> -4794398 | W15: =IF(COUNT(I15:K15)=0,"—",MAX(I15:K15)) -> — | X15: =IF(COUNT(L15:N15)=0,"—",MAX(L15:N15)) -> -4795299 | Y15: =O15 -> -4793652
B17: Spreads (worst − best) run from 9 HV (Hill Climbing, small-graph, second session) to 281,976 HV (fcmaes, synth-7). Best of three rewards spread: on small-graph and synth-5 it names a different winner than the median does.

Sheet Instances
A1: The ten instances — size, structure, and how much room is left
A2: Within each family n is identical, the edge counts agree to within two, and only the structure differs, so a ranking that changes between families is a statement about structure rather than size. “Provable ceiling” is bound.py --all: no submission can ever pass it.
A4: # | B4: Instance | C4: Family | D4: n | E4: Edges | F4: tw ≥ | G4: Provable ceiling | H4: Best in study | I4: Gap to ceiling | J4: Legal points from a random ordering | K4: Legal points from min-degree | L4: Origin
A5: 1 | B5: small-graph | C5: Sparse | D5: 1357 | E5: 2280 | F5: 5 | G5: =INDEX(Results!$C$5:$C$17,MATCH($B5,Results!$B$5:$B$17,0)) -> -1841434 | H5: =INDEX(Results!$I$5:$I$17,MATCH($B5,Results!$B$5:$B$17,0)) -> -1827490 | I5: =(G5-H5)/G5 -> 0.0075723594 | J5: 117 | K5: 22 | L5: ESA SpOC-3 official
A6: 2 | B6: synth-1 | C6: Sparse | D6: 1357 | E6: 2282 | F6: 5 | G6: =INDEX(Results!$C$5:$C$17,MATCH($B6,Results!$B$5:$B$17,0)) -> -1841434 | H6: =INDEX(Results!$I$5:$I$17,MATCH($B6,Results!$B$5:$B$17,0)) -> -1819934 | I6: =(G6-H6)/G6 -> 0.011675683 | J6: 250 | K6: 18 | L6: generate.py — 10×115 grid + 207 pendants, seed 1
A7: 3 | B7: synth-2 | C7: Sparse | D7: 1357 | E7: 2282 | F7: 5 | G7: =INDEX(Results!$C$5:$C$17,MATCH($B7,Results!$B$5:$B$17,0)) -> -1841434 | H7: =INDEX(Results!$I$5:$I$17,MATCH($B7,Results!$B$5:$B$17,0)) -> -1820165 | I7: =(G7-H7)/G7 -> 0.011550237 | J7: 297 | K7: 19 | L7: generate.py — same recipe, seed 2
A8: 4 | B8: synth-3 | C8: Sparse | D8: 1357 | E8: 2282 | F8: 5 | G8: =INDEX(Results!$C$5:$C$17,MATCH($B8,Results!$B$5:$B$17,0)) -> -1841434 | H8: =INDEX(Results!$I$5:$I$17,MATCH($B8,Results!$B$5:$B$17,0)) -> -1819944 | I8: =(G8-H8)/G8 -> 0.011670253 | J8: 295 | K8: 19 | L8: generate.py — same recipe, seed 3
A9: 5 | B9: medium-graph | C9: Rewired medium | D9: 1399 | E9: 13799 | F9: 63 | G9: =INDEX(Results!$C$5:$C$17,MATCH($B9,Results!$B$5:$B$17,0)) -> -1955110 | H9: =INDEX(Results!$I$5:$I$17,MATCH($B9,Results!$B$5:$B$17,0)) -> -1682428 | I9: =(G9-H9)/G9 -> 0.13947144 | J9: 0 | K9: 285 | L9: ESA SpOC-3 official
A10: 6 | B10: synth-4 | C10: Rewired medium | D10: 1399 | E10: 13799 | F10: 72 | G10: =INDEX(Results!$C$5:$C$17,MATCH($B10,Results!$B$5:$B$17,0)) -> -1954471 | H10: =INDEX(Results!$I$5:$I$17,MATCH($B10,Results!$B$5:$B$17,0)) -> -1592317 | I10: =(G10-H10)/G10 -> 0.18529515 | J10: 0 | K10: 312 | L10: rewire of medium-graph, seed 1 (1.5% edge overlap)
A11: 7 | B11: synth-5 | C11: Rewired medium | D11: 1399 | E11: 13799 | F11: 73 | G11: =INDEX(Results!$C$5:$C$17,MATCH($B11,Results!$B$5:$B$17,0)) -> -1954395 | H11: =INDEX(Results!$I$5:$I$17,MATCH($B11,Results!$B$5:$B$17,0)) -> -1597450 | I11: =(G11-H11)/G11 -> 0.18263708 | J11: 0 | K11: 349 | L11: rewire of medium-graph, seed 2 (1.5% edge overlap)
A12: 8 | B12: large-graph | C12: Clique-pinned | D12: 2426 | E12: 253895 | F12: 499 | G12: =INDEX(Results!$C$5:$C$17,MATCH($B12,Results!$B$5:$B$17,0)) -> -5754421 | H12: =INDEX(Results!$I$5:$I$17,MATCH($B12,Results!$B$5:$B$17,0)) -> -5329389 | I12: =(G12-H12)/G12 -> 0.073861819 | J12: 0 | K12: 500 | L12: ESA SpOC-3 official — planted 500-clique
A13: 9 | B13: synth-6 | C13: Clique-pinned | D13: 2426 | E13: 253895 | F13: 499 | G13: =INDEX(Results!$C$5:$C$17,MATCH($B13,Results!$B$5:$B$17,0)) -> -5754421 | H13: =INDEX(Results!$I$5:$I$17,MATCH($B13,Results!$B$5:$B$17,0)) -> -5167178 | I13: =(G13-H13)/G13 -> 0.10205075 | J13: 0 | K13: 500 | L13: rewire of large-graph, seed 1 — cliques 500/400/300
A14: 10 | B14: synth-7 | C14: Clique-pinned | D14: 2426 | E14: 253895 | F14: 499 | G14: =INDEX(Results!$C$5:$C$17,MATCH($B14,Results!$B$5:$B$17,0)) -> -5754421 | H14: =INDEX(Results!$I$5:$I$17,MATCH($B14,Results!$B$5:$B$17,0)) -> -5203583 | I14: =(G14-H14)/G14 -> 0.095724314 | J14: 0 | K14: 500 | L14: rewire of large-graph, seed 2 — cliques 500/400/300
B16: Reading the ceiling. A gap is two unknowns added together — how far the best result is from the optimum, plus how far the bound is from the optimum — and they cannot be separated. Where the gap is small both must be small, so the reading is definite: the sparse family is within ~1.2% of a provable ceiling and is effectively solved. Where it is wide, suspect the bound: on 1,399 vertices a treewidth lower bound of 63–73 subtracts only 2,091–2,806 from n² = 1,957,201, so the medium family's 14–19% is mostly slack in the bound. The three 2,426-vertex instances are the exception — their treewidth is pinned to 499 or 500, essentially known exactly, so their gap is real headroom. That is where a better construction pays, and where it is measured paying (README §15.3).
B22: Why the starting point is equalised. On six of the ten instances a random ordering yields no legal point at all: somewhere in its elimination a vertex exceeds the 500-width cap. ESA's published evaluator then scores the vector as width 501 — and this harness, more strictly, discards it — and every neighbouring ordering breaks the cap too, so a local search starting there stands on a plateau with nothing to climb. Both permutation-space solvers therefore start from the same min-degree construction, computed fresh inside each run. The two weight-space solvers never see a random ordering: their first candidate is already sorted by a degree-and-spectral score (README §10.4).

Sheet Operator ablation
A1: Operator ablation — seventeen move operators against the baseline's own noise
A2: Each row is hill climbing with its move pool restricted to one operator, 1,200 s × 3 seeds × 10 instances, best of 3, summed. Source: harness/ablation_more-*.csv via ablation_more.py.
B4: Baseline sample 1 | D4: -26412158 | E4: benchmark-hill_climbing.csv
B5: Baseline sample 2 | D5: -26390639 | E5: benchmark-hill_climbing-v2.csv — the sample this ablation was scored against
B6: Re-sample error | D6: =ABS(D4-D5) -> 21519 | E6: the same method run twice. Any effect smaller than this is not established.
A8: # | B8: Operator | C8: Family | D8: Total, 10 instances | E8: vs baseline sample 2 | F8: vs baseline sample 1 | G8: Sign flips | H8: Wins | I8: Ties | J8: Losses | K8: Accepted moves | L8: × re-sample error | M8: Verdict | N8: Note
A9: 1 | B9: k_opt_aimed | C9: aimed | D9: -26402010 | E9: =$D$5-D9 -> 11371 | F9: =$D$4-D9 -> -10148 | G9: =IF(SIGN(E9)<>SIGN(F9),"yes","no") -> yes | H9: 2 | I9: 8 | J9: 0 | K9: 53 | L9: =ABS(E9)/ABS($D$6) -> 0.52841675 | M9: =IF(L9>=1,"established","not established") -> not established | N9: the only variant that clears the v3 floor anywhere — on synth-4 and synth-5; at the seed level it wins nowhere
A10: 2 | B10: three_opt | C10: k-opt | D10: -26394502 | E10: =$D$5-D10 -> 3863 | F10: =$D$4-D10 -> -17656 | G10: =IF(SIGN(E10)<>SIGN(F10),"yes","no") -> yes | H10: 0 | I10: 10 | J10: 0 | K10: 137 | L10: =ABS(E10)/ABS($D$6) -> 0.17951578 | M10: =IF(L10>=1,"established","not established") -> not established
A11: 3 | B11: corner_shuffle | C11: corner | D11: -26394235 | E11: =$D$5-D11 -> 3596 | F11: =$D$4-D11 -> -17923 | G11: =IF(SIGN(E11)<>SIGN(F11),"yes","no") -> yes | H11: 0 | I11: 10 | J11: 0 | K11: 118 | L11: =ABS(E11)/ABS($D$6) -> 0.16710814 | M11: =IF(L11>=1,"established","not established") -> not established
A12: 4 | B12: or_opt | C12: k-opt | D12: -26393679 | E12: =$D$5-D12 -> 3040 | F12: =$D$4-D12 -> -18479 | G12: =IF(SIGN(E12)<>SIGN(F12),"yes","no") -> yes | H12: 0 | I12: 10 | J12: 0 | K12: 185 | L12: =ABS(E12)/ABS($D$6) -> 0.14127051 | M12: =IF(L12>=1,"established","not established") -> not established
A13: 5 | B13: min_fill_aimed | C13: aimed | D13: -26389902 | E13: =$D$5-D13 -> -737 | F13: =$D$4-D13 -> -22256 | G13: =IF(SIGN(E13)<>SIGN(F13),"yes","no") -> no | H13: 0 | I13: 10 | J13: 0 | K13: 32 | L13: =ABS(E13)/ABS($D$6) -> 0.034248803 | M13: =IF(L13>=1,"established","not established") -> not established
A14: 6 | B14: all 17, competing | C14: all | D14: -26389901 | E14: =$D$5-D14 -> -738 | F14: =$D$4-D14 -> -22257 | G14: =IF(SIGN(E14)<>SIGN(F14),"yes","no") -> no | H14: 0 | I14: 10 | J14: 0 | K14: 537 | L14: =ABS(E14)/ABS($D$6) -> 0.034295274 | M14: =IF(L14>=1,"established","not established") -> not established | N14: the whole pool drawn uniformly
A15: 7 | B15: simplicial_pull | C15: structure | D15: -26389816 | E15: =$D$5-D15 -> -823 | F15: =$D$4-D15 -> -22342 | G15: =IF(SIGN(E15)<>SIGN(F15),"yes","no") -> no | H15: 0 | I15: 10 | J15: 0 | K15: 9 | L15: =ABS(E15)/ABS($D$6) -> 0.038245272 | M15: =IF(L15>=1,"established","not established") -> not established
A16: 8 | B16: k_opt_rotate | C16: k-opt | D16: -26389244 | E16: =$D$5-D16 -> -1395 | F16: =$D$4-D16 -> -22914 | G16: =IF(SIGN(E16)<>SIGN(F16),"yes","no") -> no | H16: 0 | I16: 10 | J16: 0 | K16: 161 | L16: =ABS(E16)/ABS($D$6) -> 0.064826432 | M16: =IF(L16>=1,"established","not established") -> not established
A17: 9 | B17: three_opt_aimed | C17: aimed | D17: -26389039 | E17: =$D$5-D17 -> -1600 | F17: =$D$4-D17 -> -23119 | G17: =IF(SIGN(E17)<>SIGN(F17),"yes","no") -> no | H17: 0 | I17: 10 | J17: 0 | K17: 69 | L17: =ABS(E17)/ABS($D$6) -> 0.074352897 | M17: =IF(L17>=1,"established","not established") -> not established
A18: 10 | B18: min_fill_window | C18: min-fill | D18: -26387771 | E18: =$D$5-D18 -> -2868 | F18: =$D$4-D18 -> -24387 | G18: =IF(SIGN(E18)<>SIGN(F18),"yes","no") -> no | H18: 0 | I18: 10 | J18: 0 | K18: 44 | L18: =ABS(E18)/ABS($D$6) -> 0.13327757 | M18: =IF(L18>=1,"established","not established") -> not established
A19: 11 | B19: degeneracy_window | C19: structure | D19: -26385322 | E19: =$D$5-D19 -> -5317 | F19: =$D$4-D19 -> -26836 | G19: =IF(SIGN(E19)<>SIGN(F19),"yes","no") -> no | H19: 0 | I19: 10 | J19: 0 | K19: 75 | L19: =ABS(E19)/ABS($D$6) -> 0.24708397 | M19: =IF(L19>=1,"established","not established") -> not established
A20: 12 | B20: degeneracy_aimed | C20: aimed | D20: -26384122 | E20: =$D$5-D20 -> -6517 | F20: =$D$4-D20 -> -28036 | G20: =IF(SIGN(E20)<>SIGN(F20),"yes","no") -> no | H20: 0 | I20: 10 | J20: 0 | K20: 9 | L20: =ABS(E20)/ABS($D$6) -> 0.30284865 | M20: =IF(L20>=1,"established","not established") -> not established
A21: 13 | B21: or_opt_aimed | C21: aimed | D21: -26378836 | E21: =$D$5-D21 -> -11803 | F21: =$D$4-D21 -> -33322 | G21: =IF(SIGN(E21)<>SIGN(F21),"yes","no") -> no | H21: 0 | I21: 10 | J21: 0 | K21: 10 | L21: =ABS(E21)/ABS($D$6) -> 0.54849203 | M21: =IF(L21>=1,"established","not established") -> not established
A22: 14 | B22: corner_earlier | C22: corner | D22: -26376380 | E22: =$D$5-D22 -> -14259 | F22: =$D$4-D22 -> -35778 | G22: =IF(SIGN(E22)<>SIGN(F22),"yes","no") -> no | H22: 0 | I22: 10 | J22: 0 | K22: 0 | L22: =ABS(E22)/ABS($D$6) -> 0.66262373 | M22: =IF(L22>=1,"established","not established") -> not established | N22: never fires: zero accepted moves in 30 runs
B24: What the table says. Thirteen of the fourteen variants do not separate from the baseline on a single instance: ten ties, no losses, no wins. The four that come out ahead of baseline sample 2 all come out behind baseline sample 1 — the Sign flips column — so their sign is a property of which run of the control was drawn, not of the operator. The largest effect in the table is 0.7× the amount the baseline differs from itself. An effect that changes sign when the control is re-drawn was never there.
B29: Wins, ties and losses count instances, not seeds: a win is an instance where the variant beats baseline sample 2 by at least the per-instance floor of 7,881 HV, a loss is the same margin the other way. Accepted moves are summed over all 30 runs — corner_earlier accepted nothing at all in 36,000 seconds of searching.
B33: At the seed level the answer is the same. Against both control samples pooled — six seeds — no arm's three seeds beat all six control seeds on any instance, k_opt_aimed included; most arms lose three or four instances that way, by small margins (harness/robustness.py, block C). 48 of the 420 runs overran the 1,200 s budget because the machine stalled — small-graph seed 3, for one, ran 4,275 s for every arm at once. A stall costs a wall-clock-bounded run search time, so it biases against the arms, not for them.

Sheet Budget sweep
A1: Budget sweep — does more time let search catch the construction?
A2: Four arms × three budgets × ten instances × three seeds, best of 3, summed — all on one machine so budget is the only thing that varies. Three budgets rather than two, because two points cannot show the shape of the curve. Source: results/budget_sweep.csv via run_budget_sweep.sh and merge_budget_sweep.py.
A4: Arm | B4: Kind | C4: 1,200 s | D4: 3,600 s | E4: 12,000 s | F4: Gained over 10× budget | G4: Behind construction at 12,000 s | H4: What it is
A5: grasp_front | B5: construction | C5: -26781700 | D5: -26762079 | E5: -26692166 | F5: =C5-E5 -> -89534 | H5: the construction lever — what search has to catch
A6: hill_climbing | B6: search | C6: -26389516 | D6: -26404696 | E6: -26422559 | F6: =C6-E6 -> 33043 | G6: =E6-E$5 -> 269607 | H6: the published four-operator baseline
A7: all 17 | B7: search | C7: -26391399 | D7: -26393577 | E7: -26396957 | F7: =C7-E7 -> 5558 | G7: =E7-E$5 -> 295209 | H7: the seventeen-operator pool
A8: hc_bottleneck | B8: search | C8: -26392654 | D8: -26388897 | E8: -26401668 | F8: =C8-E8 -> 9014 | G8: =E8-E$5 -> 290498 | H8: the move-pool lever
A10: How far search is from the construction
A11: lead over | C11: 1,200 s | D11: 3,600 s | E11: 12,000 s | F11: lead vs construction mean, 12,000 s | G11: gained over 10× budget | H11: gain ÷ lead
A12: =A6 -> hill_climbing | C12: =C6-C$5 -> 392184 | D12: =D6-D$5 -> 357383 | E12: =E6-E$5 -> 269607 | F12: =E6-AVERAGE($C$5:$E$5) -> 322756 | G12: =F6 -> 33043 | H12: =G12/F12 -> 0.10237765
A13: =A7 -> all 17 | C13: =C7-C$5 -> 390301 | D13: =D7-D$5 -> 368502 | E13: =E7-E$5 -> 295209 | F13: =E7-AVERAGE($C$5:$E$5) -> 348358 | G13: =F7 -> 5558 | H13: =G13/F13 -> 0.015954851
A14: =A8 -> hc_bottleneck | C14: =C8-C$5 -> 389046 | D14: =D8-D$5 -> 373182 | E14: =E8-E$5 -> 290498 | F14: =E8-AVERAGE($C$5:$E$5) -> 343647 | G14: =F8 -> 9014 | H14: =G14/F14 -> 0.026230405
A16: What it answers. More time helps search a little: hill climbing gains 33,043 HV from 1,200 s to 12,000 s — about 1.5× the 21,519 HV its own ten-instance total moves when it is simply run again. The construction leads every search arm at every budget, by 269,607 to 392,184 HV, and ten times the budget recovers about a tenth of that lead at best (10% for hill climbing, 3% for the move pool, 2% for all 17 operators, against the construction's mean). grasp_front's own total moves by 89,534 HV across the three budgets, but it draws different constructions at each budget, and with one draw per budget that movement cannot be read as a trend. An earlier reading of this sheet counted it as search closing the gap — “31% closed”, a crossover “near thirty times the budget, about ten hours” — and is withdrawn: 89,534 of the 122,577 HV it called closing was the construction getting a worse draw. No crossover is in sight at 10×, and three points cannot say where one would be (harness/robustness.py, block D).
A22: A second reading. The seventeen-operator pool gains 5,558 HV over the same 10×, against hill climbing's 33,043, and goes from 1,883 HV ahead of it at 1,200 s to 25,602 HV behind at 12,000 s. That is suggestive, not established — 25,602 is 1.2× the baseline's own re-draw and rests on one sample per budget — but nothing here suggests more operators help when they are given more time.
A26: Scores are negative hypervolume, so a more negative total is better: a positive “gained over 10× budget” means the arm improved with more time, and a negative one — grasp_front — means it scored worse.

Sheet Notes and provenance
B1: Notes and provenance
B2: Read this before quoting any row of Results. Everything below is traceable to a file in this repository; the rule the project keeps is that a number which does not appear in the output of report.py or robustness.py does not belong in the sheet.
B6: Protocol
B7: 1,200 s per instance per seed, 3 seeds; the method columns report the best of 3 and the verdicts read all three (Seeds sheet). fcmaes, Team HRI, Hill Climbing and min-degree run on one CPU core each via harness/bench_one.py. Spacekangaroos is the real cuda-torso entry on a Kaggle NVIDIA T4 at batch 1,024, reduced to 512 at n = 2,426 so the two B×N×N bool tensors fit in GPU memory (harness/spoc3_benchmark.ipynb). Every result, whatever produced it, is re-scored and validated through the same esa_eval.py, so the columns are comparable. Four runs fall outside the 1,150–1,400 s window harness/status.sh flags (Hill Climbing synth-6 seeds 1–2; fcmaes and Team HRI synth-7 seed 1); none of them supplies a best-of-3 value.
B12: Equal wall-clock is not equal computation. Left alone, the competitors' numerical libraries kept about nine cores busy (929% CPU) while Hill Climbing, pure Python, uses one. So every CPU solver here is pinned to one core: run_mac.sh sets the thread limits and bench_one.py refuses to run without them. Pinning has a price, stated so it is not mistaken for a weakness of the method: on small-graph at 30 s it costs fast-cma-es about 20% of its evaluations (README §10.5). Spacekangaroos runs on its own GPU and is not affected.
B19: Where each column comes from
B20: Column | C20: Source file | D20: What it is
B21: Provable ceiling | C21: bound.py --all | D21: The most negative score any method could ever report, from tw(G) ≤ tw(torso(G,S)) + t with a cheap treewidth lower bound. Provable, deterministic, independent of every solver here.
B22: fcmaes | C22: harness/benchmark-fast_cma_es.csv | D22: leaderboard-references/cmaes.py — separable CMA-ES over weight vectors, ported from the fast-cma-es approach. Best of seeds 1–3.
B23: Team HRI | C23: harness/benchmark-hri.csv | D23: leaderboard-references/hri_lns.py — multi-objective LNS reimplemented from their paper; no source was published. Not their code. Best of seeds 1–3.
B24: Spacekangaroos | C24: harness/benchmark-spacekangaroos.csv | D24: The winning entry's own cuda-torso, run unmodified except for a 32-bit overflow fix in libeval.cu (adj_offset int → size_t) and the batch reduction above. Best of seeds 1–3.
B25: Hill Climbing | C25: harness/benchmark-hill_climbing.csv | D25: hill_climbing.py, this study's method. A second independent full-budget sample is in benchmark-hill_climbing-v2.csv; the difference between the two is the significance floor below. Best of seeds 1–3.
B26: min-degree ×8 | C26: harness/benchmark-min_degree-x8.csv | D26: Best of eight greedy min-degree constructions with random tie-breaking, seeds 1–8 — what Hill Climbing builds before it searches. Tie-breaking is random, so the seed set is part of the result. Regenerate with harness/min_degree_x8.py.
B27: Best in study, Best method, Margin, Verdict, Median winner, Seed gap, Floor rule, Gap, min-degree share | C27: — computed in-sheet, over the method columns and the Seeds sheet | D27: Live formulas. Nothing is typed in: correct a seed on the Seeds sheet or a method cell and every verdict re-derives. Verdict = resolved when the median names the same winner as the best of 3 and every seed of the winner beats every seed of every rival (Seed gap > 0).
B28: ESA leaderboard | C28: published ESA SpOC-3 leaderboard | D28: Top score on the official three instances only, set under the leaderboard's own protocol — not this benchmark's 1,200 s single-core budget, and not comparable to the columns to its left. The seven synthetic instances are new and have no leaderboard, which is why they read n/a. Kept in the sheet as an external reference point and nothing more.
B31: How big a difference has to be
B32: Every method ran three seeds, and Hill Climbing was run twice at full budget, so two kinds of noise can be measured: the spread of each method's own seeds, and how far a whole session can move. They answer different questions, and neither is a single number that can judge every row:
B36: Figure | C36: Value | D36: Use it for
B37: Each method's own three seeds | C37: Seeds sheet | D37: A single row. Seed spreads run from 9 HV to 281,976 HV depending on method and instance — four orders of magnitude — which is why one floor cannot judge every row. A row is resolved only when every seed of the winner beats every seed of every rival (an exact rank test, p = 0.05 with three seeds a side) and the median names the same winner.
B38: Worst single instance moved, between the two sessions | C38: 7,881 HV | D38: Nothing on its own. It is one method's noise on one instance (synth-4) and exactly what synth-4's own 13,214 HV seed spread predicts; reshuffling seeds between sessions finds no per-instance session effect. Kept as the Floor rule (v3) column so the change of rule stays visible.
B39: Ten-instance total moved, between the two sessions | C39: 21,519 HV | D39: A ten-instance sum, such as an ablation's net HV. Reshuffling Hill Climbing's six seeds per instance between the sessions moves the total that far only 4.6% of the time (robustness.py, block B): sessions do differ a little, so an aggregate claim needs a control that was actually run again. (The median within-run seed spread of the Block-2 solvers, 1,528 HV, is a per-instance figure and belongs against neither.)
B41: Judged on their own seeds, five of the ten rows are unresolved: small-graph (best of 3 names Spacekangaroos, the median names Team HRI), synth-1, synth-2 (the median names Hill Climbing), medium-graph (Team HRI's seeds span 80,376 HV) and synth-5 (best of 3 names Team HRI on one outlier seed; the median names fcmaes). Resolved: synth-3 (Hill Climbing, by 71 HV over its own starting point — consistent but negligible), synth-4 (Team HRI) and the three dense rows (fcmaes). The v3 rule, one 7,881 HV floor for everything, got four of the ten rows wrong: it called synth-3 and synth-4 ties and medium-graph and synth-5 separated. An earlier note said the baseline differs from itself by fourteen times the seed spread; that compared a ten-instance sum with a one-instance median and is withdrawn.
B46: synth-3 is the clearest case. The 20-minute search reaches −1,819,944; eight min-degree constructions reach −1,819,873 in under a second. The search contributes 71 HV, or 0.004% — and does so on every seed, which is why the row counts as resolved and why resolved is not the same as important. On the sparse family the bi-objective problem collapses in practice to minimising the width of the whole graph, because a single point at t = 0 carries 99.99% of the construction's score on small-graph — so there is almost nothing left for any search to win there (README §15.4).
B52: What this table does not establish
B53: Three seeds per cell, and the method columns report the best of three. min() over three samples is a biased estimator and the bias is not neutral between methods: it rewards whichever has the higher variance, because best-of-k climbs with spread. The Seeds sheet shows it happening — on small-graph and synth-5 the best of three crowns a different method than the median — which is why the verdicts read all three seeds and not the best.
B57: Three seeds is the smallest sample that can separate at all. Complete separation of three seeds against three happens by chance with probability 1/20, so a resolved row is a p = 0.05 statement: strong where the seed gap is large (the dense rows clear it by 121,598–425,344 HV), to be held loosely where it is not (synth-4 by 2,128 HV, synth-3 by 24 HV).
B60: Runs are not reproducible, only re-samplable. The climb loop is wall-clock-bounded, so iteration counts differ between sessions and no run here can be reproduced exactly. An attempt to verify a run by re-running it mismatched on 29 of 30 rows, and the check, not the harness, was wrong.
B64: Ten instances, and the dense family is three variants of one graph. large-graph, synth-6 and synth-7 all carry a planted 500-clique, and that family is where every large margin in this table is made. Two of the three were generated to resemble the first, so they are not independently chosen. Any claim about dense instances rests on a thin base.
B68: Half the rows are unresolved. The Verdict column marks them and the third scoreboard line counts them; the table supports five findings, not ten — and not the same five the v3 floor picked.
B71: One budget per cell. Everything in Results is 1,200 s, and the construction is a one-off cost paid at the start while the search is what the remaining budget buys — so the ratio between them is a function of the budget. That is no longer an open question: the Budget sweep sheet measures it at 1,200 / 3,600 / 12,000 s and reports what it found.
B76: Previous revision (v3)
B77: Changed | C77: From | D77: To
B78: min-degree ×8 column | C78: no committed source file; 4 of 10 cells not reproducible | D78: harness/benchmark-min_degree-x8.csv + min_degree_x8.py, seeds 1–8. small-graph −1,813,181→−1,814,518 · medium-graph −1,615,495→−1,606,387 · synth-4 −1,553,005→−1,554,095 · synth-5 −1,560,655→−1,558,465. No winner and no verdict changes.
B79: Significance floor | C79: 2,470 HV, described as the median spread across seeds — a figure that appears in no source file | D79: 7,881 HV, the per-instance between-run figure from README §13.1, in an editable cell that drives every Verdict.
B80: Ties | C80: 3 rows marked, by hand | D80: 5 rows, decided by formula. synth-4 and small-graph were missing. synth-3's margin was given as 2,304 HV against Team HRI when second place is min-degree ×8.
B81: “Best Known” | C81: one column holding the ESA leaderboard top on three rows and the in-study best on seven — two different things under two different protocols | D81: split into Best in study (formula over the five method columns) and ESA leaderboard (external, official three instances only).
B82: “Gap from Best” | C82: labelled as the gap from best, but the formula read column I and so silently reported Hill Climbing's gap. Its reference column was empty, so it rendered blank throughout | D82: Gap to ceiling — best in study against the provable bound from bound.py. Plus min-degree share, which is the construction-versus-search comparison the write-up is about.
B83: Upper Bound column | C83: present and completely empty | D83: filled for all ten instances from bound.py --all, and the spine of the Instances sheet.
B84: Row order | C84: official three, then synth-1–7 | D84: grouped into the three structural families, each a set of matched instances with identical n and edge count. The ranking changes between families; that is the result.
B85: Readability | C85: every data cell filled dark teal #356854 with theme-black text, header row unfilled; footnotes living inside the table body as instance rows 11–18; three Excel tables stretched over 290 empty rows; no frozen header | D85: dark band reserved for the header, light zebra body, winners highlighted, notes moved here, empty rows and the three empty columns removed, header frozen and set to repeat on every printed page.
...

Sheet Audit
A1: Audit — what was checked for v4, and what it found
A2: Each row is one check, run against the files named in Source. PASS = matches; FIXED = wrong or misleading in v3 and corrected here; NOTE = correct, but worth knowing before quoting.
A4: # | B4: Sheet · cells | C4: Check | D4: Result | E4: Status | F4: Source
A5: 1 | B5: Results · D6:H17 | C5: Best-of-3 per method against the CSVs | D5: 47 values match exactly; the 3 em-dashes are runs with valid = False | E5: PASS | F5: harness/benchmark-*.csv
A6: 2 | B6: Results · C6:C17 | C6: Provable ceiling | D6: 10/10 match bound.py --all | E6: PASS | F6: bound.py --all
A7: 3 | B7: Results · I, J, K | C7: Best in study, best method, margin over 2nd | D7: recomputed independently; all match | E7: PASS | F7: robustness.py block A
A8: 4 | B8: Results · M, N | C8: Gap to ceiling, min-degree share | D8: recomputed; all match | E8: PASS | F8: bound.py, CSVs
A9: 5 | B9: Results · O6, O11, O15 | C9: ESA leaderboard top scores | D9: −1,829,919 / −1,745,122 / −5,493,062 as published | E9: PASS | F9: optimise.esa.int, read 2026-10-13; leaderboard-references/esa_leaderboard.csv
A10: 6 | B10: Results · L | C10: Verdict rule | D10: one 7,881 HV floor misjudges 4 rows; method seed spreads reach 281,976 HV | E10: FIXED | F10: Seeds sheet, robustness.py block A
A11: 7 | B11: Results · C19 | C11: Significance floor | D11: 7,881 = Hill Climbing's session change on synth-4 — correct, but one method on one instance | E11: NOTE | F11: benchmark-hill_climbing*.csv
A12: 8 | B12: Results · A5, A10, A14 | C12: Family headers: n, edges, tw ranges | D12: match data/*.gr and bound.py | E12: PASS | F12: data/*.gr
A13: 9 | B13: Results · protocol | C13: 1,200 s budget held | D13: 4 runs outside 1,150–1,400 s; none supplies a best-of-3 value | E13: NOTE | F13: seconds column of the CSVs
A14: 10 | B14: Seeds · C6:O15 | C14: Every seed against its CSV row | D14: 150 runs, all match | E14: PASS | F14: harness/benchmark-*.csv
A15: 11 | B15: Instances · D–F | C15: n, edges, tw ≥ | D15: match data/*.gr and bound.py --all | E15: PASS | F15: data/*.gr, bound.py
A16: 12 | B16: Instances · J–K | C16: Legal points from random / min-degree | D16: match the README §10.4 measurement; no CSV holds them | E16: NOTE | F16: README §10.4
... A34: 30 | B34: External | C34: ESA's own evaluation code, run beside esa_eval.py | D34: identical on all ten instances: fitness on 220 orderings (44 over the cap), hypervolume on 2,000 point sets, and the min-degree ×8 column reproduced; data/ graphs byte-identical to ESA's | E34: PASS | F34: harness/esa_crosscheck.py, esa_crosscheck.log
